[2024-04-07T16:59:00.498-0400] {taskinstance.py:1956} INFO - Dependencies all met for dep_context=non-requeueable deps ti=<TaskInstance: datapipeline.encode_task manual__2024-04-07T20:58:23.610811+00:00 [queued]>
[2024-04-07T16:59:00.503-0400] {taskinstance.py:1956} INFO - Dependencies all met for dep_context=requeueable deps ti=<TaskInstance: datapipeline.encode_task manual__2024-04-07T20:58:23.610811+00:00 [queued]>
[2024-04-07T16:59:00.503-0400] {taskinstance.py:2170} INFO - Starting attempt 1 of 1
[2024-04-07T16:59:00.516-0400] {taskinstance.py:2191} INFO - Executing <Task(PythonOperator): encode_task> on 2024-04-07 20:58:23.610811+00:00
[2024-04-07T16:59:00.519-0400] {standard_task_runner.py:60} INFO - Started process 62666 to run task
[2024-04-07T16:59:00.522-0400] {standard_task_runner.py:87} INFO - Running: ['airflow', 'tasks', 'run', 'datapipeline', 'encode_task', 'manual__2024-04-07T20:58:23.610811+00:00', '--job-id', '344', '--raw', '--subdir', 'DAGS_FOLDER/airflow.py', '--cfg-path', '/tmp/tmp2dlkokpd']
[2024-04-07T16:59:00.524-0400] {standard_task_runner.py:88} INFO - Job 344: Subtask encode_task
[2024-04-07T16:59:00.548-0400] {task_command.py:423} INFO - Running <TaskInstance: datapipeline.encode_task manual__2024-04-07T20:58:23.610811+00:00 [running]> on host Naveen.
[2024-04-07T16:59:00.578-0400] {abstractoperator.py:707} ERROR - Exception rendering Jinja template for task 'encode_task', field 'op_kwargs'. Template: {'input_pickle_path': '{{ ti.xcom_pull(task_ids=income_normalize") }}'}
Traceback (most recent call last):
  File "/home/pasala_n/.local/lib/python3.9/site-packages/airflow/models/abstractoperator.py", line 699, in _do_render_template_fields
    rendered_content = self.render_template(
  File "/home/pasala_n/.local/lib/python3.9/site-packages/airflow/template/templater.py", line 186, in render_template
    return {k: self.render_template(v, context, jinja_env, oids) for k, v in value.items()}
  File "/home/pasala_n/.local/lib/python3.9/site-packages/airflow/template/templater.py", line 186, in <dictcomp>
    return {k: self.render_template(v, context, jinja_env, oids) for k, v in value.items()}
  File "/home/pasala_n/.local/lib/python3.9/site-packages/airflow/template/templater.py", line 173, in render_template
    template = jinja_env.from_string(value)
  File "/home/pasala_n/.local/lib/python3.9/site-packages/jinja2/environment.py", line 1105, in from_string
    return cls.from_code(self, self.compile(source), gs, None)
  File "/home/pasala_n/.local/lib/python3.9/site-packages/jinja2/environment.py", line 768, in compile
    self.handle_exception(source=source_hint)
  File "/home/pasala_n/.local/lib/python3.9/site-packages/jinja2/environment.py", line 936, in handle_exception
    raise rewrite_traceback_stack(source=source)
  File "<unknown>", line 1, in template
jinja2.exceptions.TemplateSyntaxError: unexpected char '"' at 41
[2024-04-07T16:59:00.581-0400] {taskinstance.py:2698} ERROR - Task failed with exception
Traceback (most recent call last):
  File "/home/pasala_n/.local/lib/python3.9/site-packages/airflow/models/taskinstance.py", line 2334, in _run_raw_task
    self._execute_task_with_callbacks(context, test_mode, session=session)
  File "/home/pasala_n/.local/lib/python3.9/site-packages/airflow/models/taskinstance.py", line 2465, in _execute_task_with_callbacks
    task_orig = self.render_templates(context=context)
  File "/home/pasala_n/.local/lib/python3.9/site-packages/airflow/models/taskinstance.py", line 2877, in render_templates
    original_task.render_template_fields(context)
  File "/home/pasala_n/.local/lib/python3.9/site-packages/airflow/models/baseoperator.py", line 1241, in render_template_fields
    self._do_render_template_fields(self, self.template_fields, context, jinja_env, set())
  File "/home/pasala_n/.local/lib/python3.9/site-packages/airflow/utils/session.py", line 79, in wrapper
    return func(*args, session=session, **kwargs)
  File "/home/pasala_n/.local/lib/python3.9/site-packages/airflow/models/abstractoperator.py", line 699, in _do_render_template_fields
    rendered_content = self.render_template(
  File "/home/pasala_n/.local/lib/python3.9/site-packages/airflow/template/templater.py", line 186, in render_template
    return {k: self.render_template(v, context, jinja_env, oids) for k, v in value.items()}
  File "/home/pasala_n/.local/lib/python3.9/site-packages/airflow/template/templater.py", line 186, in <dictcomp>
    return {k: self.render_template(v, context, jinja_env, oids) for k, v in value.items()}
  File "/home/pasala_n/.local/lib/python3.9/site-packages/airflow/template/templater.py", line 173, in render_template
    template = jinja_env.from_string(value)
  File "/home/pasala_n/.local/lib/python3.9/site-packages/jinja2/environment.py", line 1105, in from_string
    return cls.from_code(self, self.compile(source), gs, None)
  File "/home/pasala_n/.local/lib/python3.9/site-packages/jinja2/environment.py", line 768, in compile
    self.handle_exception(source=source_hint)
  File "/home/pasala_n/.local/lib/python3.9/site-packages/jinja2/environment.py", line 936, in handle_exception
    raise rewrite_traceback_stack(source=source)
  File "<unknown>", line 1, in template
jinja2.exceptions.TemplateSyntaxError: unexpected char '"' at 41
[2024-04-07T16:59:00.586-0400] {taskinstance.py:1138} INFO - Marking task as FAILED. dag_id=datapipeline, task_id=encode_task, execution_date=20240407T205823, start_date=20240407T205900, end_date=20240407T205900
[2024-04-07T16:59:00.597-0400] {standard_task_runner.py:107} ERROR - Failed to execute job 344 for task encode_task (unexpected char '"' at 41; 62666)
[2024-04-07T16:59:00.615-0400] {local_task_job_runner.py:234} INFO - Task exited with return code 1
[2024-04-07T16:59:00.630-0400] {taskinstance.py:3280} INFO - 0 downstream tasks scheduled from follow-on schedule check
