[2024-04-07T17:06:18.656-0400] {taskinstance.py:1956} INFO - Dependencies all met for dep_context=non-requeueable deps ti=<TaskInstance: datapipeline.split_task manual__2024-04-07T21:05:31.570075+00:00 [queued]>
[2024-04-07T17:06:18.661-0400] {taskinstance.py:1956} INFO - Dependencies all met for dep_context=requeueable deps ti=<TaskInstance: datapipeline.split_task manual__2024-04-07T21:05:31.570075+00:00 [queued]>
[2024-04-07T17:06:18.661-0400] {taskinstance.py:2170} INFO - Starting attempt 1 of 1
[2024-04-07T17:06:18.673-0400] {taskinstance.py:2191} INFO - Executing <Task(PythonOperator): split_task> on 2024-04-07 21:05:31.570075+00:00
[2024-04-07T17:06:18.677-0400] {standard_task_runner.py:60} INFO - Started process 66464 to run task
[2024-04-07T17:06:18.680-0400] {standard_task_runner.py:87} INFO - Running: ['airflow', 'tasks', 'run', 'datapipeline', 'split_task', 'manual__2024-04-07T21:05:31.570075+00:00', '--job-id', '357', '--raw', '--subdir', 'DAGS_FOLDER/airflow.py', '--cfg-path', '/tmp/tmpfg7hig2q']
[2024-04-07T17:06:18.682-0400] {standard_task_runner.py:88} INFO - Job 357: Subtask split_task
[2024-04-07T17:06:18.709-0400] {task_command.py:423} INFO - Running <TaskInstance: datapipeline.split_task manual__2024-04-07T21:05:31.570075+00:00 [running]> on host Naveen.
[2024-04-07T17:06:18.762-0400] {taskinstance.py:2480} INFO - Exporting env vars: AIRFLOW_CTX_DAG_OWNER='your_name' AIRFLOW_CTX_DAG_ID='datapipeline' AIRFLOW_CTX_TASK_ID='split_task' AIRFLOW_CTX_EXECUTION_DATE='2024-04-07T21:05:31.570075+00:00' AIRFLOW_CTX_TRY_NUMBER='1' AIRFLOW_CTX_DAG_RUN_ID='manual__2024-04-07T21:05:31.570075+00:00'
[2024-04-07T17:06:19.223-0400] {taskinstance.py:2698} ERROR - Task failed with exception
Traceback (most recent call last):
  File "/home/pasala_n/.local/lib/python3.9/site-packages/airflow/models/taskinstance.py", line 433, in _execute_task
    result = execute_callable(context=context, **execute_callable_kwargs)
  File "/home/pasala_n/.local/lib/python3.9/site-packages/airflow/operators/python.py", line 199, in execute
    return_value = self.execute_callable()
  File "/home/pasala_n/.local/lib/python3.9/site-packages/airflow/operators/python.py", line 216, in execute_callable
    return self.python_callable(*self.op_args, **self.op_kwargs)
  File "/home/pasala_n/MLOPS_Credit_latest/MLOPSPROJECT/dags/src/split.py", line 34, in split
    y_train.to_parquet(ytrain_path)
  File "/home/pasala_n/.local/lib/python3.9/site-packages/pandas/core/generic.py", line 6296, in __getattr__
    return object.__getattribute__(self, name)
AttributeError: 'Series' object has no attribute 'to_parquet'
[2024-04-07T17:06:19.232-0400] {taskinstance.py:1138} INFO - Marking task as FAILED. dag_id=datapipeline, task_id=split_task, execution_date=20240407T210531, start_date=20240407T210618, end_date=20240407T210619
[2024-04-07T17:06:19.243-0400] {standard_task_runner.py:107} ERROR - Failed to execute job 357 for task split_task ('Series' object has no attribute 'to_parquet'; 66464)
[2024-04-07T17:06:19.262-0400] {local_task_job_runner.py:234} INFO - Task exited with return code 1
[2024-04-07T17:06:19.275-0400] {taskinstance.py:3280} INFO - 0 downstream tasks scheduled from follow-on schedule check
